Workbook

Sheet Presupuestos
B3: PRESUPUESTO 2023 | H3: GASTADO EN PUBLICACIONES
H4: Año 1- 2023 | I4: =C8 -> 21306291
B5: PRESUPUESTO 2023 | C5: 21306291 | H5: Año 2- 2024 | I5: =C18 -> 20363281
B6: 17 pub. Inf. Avance 1-2023 | H6: Año 3- 2025 | I6: =I46 -> 38576153 | J6: al 15 de octubre 2025
B7: 11 financiadas | C7: 21306291
B8: Total gastado | C8: 21306291
B9: POR GASTAR | C9: =C5-C8 -> 0 | H9: TOTAL | I9: =SUM(I4:I6) -> 80245725
B12: al 15 de mayo 2025
B13: PRESUPUESTO 2024
B15: PRESUPUESTO UC-Inicial | C15: 36000000 | D15: PRESUPUESTO UCH | E15: 0
B16: PRESUPUESTO UC- Final | C16: 40385822
B17: 31 pub. Inf Avance 02-2024
B18: 10 financiadas (100%) 3 financiadas (50%) | C18: 20363281
B19: 8 pub. Inf Avance 03-2025
B20: 8 financiadas (100%) 1 financiadas (50%) | C20: 20022541
B21: Total gastado | C21: =C18+C20 -> 40385822 | E21: =E14-E17 -> 0
B22: POR GASTAR | C22: =C16-C21 -> 0 | E22: =E15-E18 -> 0
B25: al 15 de octubre 2025
B26: PRESUPUESTO 2025
B28: PRESUPUESTO UC-Inicial | C28: 30000000 | D28: PRESUPUESTO UCH | E28: 0
B29: PRESUPUESTO UC- Final | C29: 22000000 | F29: 8 publicaciones fueron financiadas con fondos 2024
B30: 48 pub. Inf Avance 03-2025
B31: 6 financiadas (100%) 1 financiadas (50%) | C31: =' Publicaciones año 3'!Z91 -> 18553612
B33: xx financiadas (100%) xx financiadas (50%)
B34: Total gastado | C34: =C31+C33 -> 18553612 | D34: POR GASTAR | E34: =E27-E30 -> 0
B35: POR GASTAR | C35: =C29-C34 -> 3446388 | E35: =E28-E31 -> 0
H37: Actualización : 15 octubre 2025
H39: PUBLICACIONES FINANCIADAS 2025
H41: 48 publicaciones informadas en Inf Avance 03-2025
H42: PRESUPUESTO UC | J42: PRESUPUESTO UCH
I43: Monto pagado
H44: 8 publicaciones financiadas (Fdos. 2024) | I44: =C20 -> 20022541 | K44: 0
H45: 6 publicaciones financiadas (Fdos. 2025) | I45: =C31 -> 18553612
H46: Total gastado | I46: =SUM(I44:I45) -> 38576153
H48: Presupuesto asignado 2025 | I48: 20000000
H49: 6 publicaciones financiadas (Fdos.2025) | I49: =C31 -> 18553612
H50: SALDO POR GASTAR | I50: =I48-I49 -> 1446388
H52: Solicitudes
H53: Susana Mondschein (sale de su ppto WP4)

Sheet Resumen publicaciones
B4: PUBLICACIONES CIENTIFICAS
B6: PUBLICACIONES | D6: Q1 | E6: % Q1 | F6: Promedio JIF | G6: Top 10% | H6: Instituciones Internacionales | I6: Instituciones Nacionales
B7: 2023 | C7: 17 publicaciones | D7: =COUNTIFS(' Publicaciones año 1'!$F$8:$F$25,"Q1") -> 9 | E7: =D7/17 -> 0.52941176 | F7: 4.3 | G7: 6 | H7: =' Publicaciones año 1'!Q25 -> 9 | I7: =' Publicaciones año 1'!S25 -> 13
B8: 2024 | C8: 31 publicaciones | D8: =COUNTIFS(' Publicaciones año 2'!$F$7:$F$38,"Q1") -> 17 | E8: =D8/31 -> 0.5483871 | F8: 4.8 | G8: 11 | H8: =' Publicaciones año 2'!O38 -> 16 | I8: =' Publicaciones año 2'!Q38 -> 19
B9: 2025 | C9: 65 publicaciones | D9: =COUNTIFS(' Publicaciones año 3'!$G$8:$G$182,"Q1") -> 27 | E9: =D9/48 -> 0.5625 | F9: =' Publicaciones año 3'!H89 -> 4.8359375 | G9: =' Publicaciones año 3'!I89 -> 13 | H9: =' Publicaciones año 3'!L90 -> 38 | I9: =' Publicaciones año 3'!N90 -> 44 | J9: al 07 de noviembre 2025

Sheet Resumen publ por WP
B1: AÑO 1 - 2023
I2: PUBLICACIONES ASOCIATIVAS
B3: PUBLICACIONES ASOCIATIVAS | I3: AÑO 1 - 2023 | J3: AÑO 2 -2024 | K3: AÑO 3 -2025
C4: AÑO 1 - 2023 | H4: Total publicaciones | I4: 17 | J4: 31 | K4: 48 | L4: hasta el 17 de octubre
B5: Total publicaciones | C5: 17 | H5: Pub. Asociativas | I5: =F16 -> 3 | J5: =F49 -> 8 | K5: =F78 -> 13
B6: Pub. Asociativas | C6: =' Publicaciones año 1'!E25 -> 3 | H6: % Asociatividad | I6: =I5/I4 -> 0.17647059 | J6: =J5/J4 -> 0.25806452 | K6: =K5/K4 -> 0.27083333
B7: % Asociatividad | C7: =C6/C5 -> 0.17647059
B10: PUBLICACIONES NO ASOCIATIVAS | E10: PUBLICACIONES ASOCIATIVAS
B12: WP | C12: AÑO 1 - 2023 | E12: WP | F12: AÑO 1 - 2023
B13: WP-1 | C13: =COUNTIFS(' Publicaciones año 1'!$D$8:$D$24,"1") -> 0 | E13: WP 1-2 | F13: 1
B14: WP-2 | C14: =COUNTIFS(' Publicaciones año 1'!$D$8:$D$24,"2") -> 4 | E14: WP 2-3 | F14: 1
B15: WP-3 | C15: =COUNTIFS(' Publicaciones año 1'!$D$8:$D$24,"3") -> 5 | E15: WP 2-4 | F15: 1
B16: WP-4 | C16: =COUNTIFS(' Publicaciones año 1'!$D$8:$D$24,"4") -> 2 | E16: TOTAL | F16: =SUM(F13:F15) -> 3
B17: WP-5 | C17: =COUNTIFS(' Publicaciones año 1'!$D$8:$D$24,"5") -> 3
B18: TOTAL | C18: =SUM(C13:C17) -> 14
B21: Presupuesto Año 1 - 2023
B22: WP | C22: Ppto WP- 2023
B23: WP-1 | C23: 64000000
B24: WP-2 | C24: 150000000
B25: WP-3 | C25: =80000000+150000000 -> 230000000 | E25: * incluye M$150.000
B26: WP-4 | C26: 90000000
B27: WP-5 | C27: 80000000
B28: TOTAL | C28: =SUM(C23:C27) -> 614000000
B32: AÑO 2 - 2024
B34: PUBLICACIONES ASOCIATIVAS
C35: AÑO 2 - 2024
B36: Total publicaciones | C36: 31
B37: Pub. Asociativas | C37: =' Publicaciones año 2'!E38 -> 8
B38: % Asociatividad | C38: =C37/C36 -> 0.25806452
B41: PUBLICACIONES NO ASOCIATIVAS | E41: PUBLICACIONES ASOCIATIVAS
B43: WP | C43: AÑO 2 -2024 | E43: WP | F43: AÑO 2 -2024
B44: WP-1 | C44: =COUNTIFS(' Publicaciones año 2'!$D$7:$D$37,"1") -> 2 | E44: WP 2-3 | F44: 3
B45: WP-2 | C45: =COUNTIFS(' Publicaciones año 2'!$D$7:$D$37,"2") -> 8 | E45: WP 2-4 | F45: 1
B46: WP-3 | C46: =COUNTIFS(' Publicaciones año 2'!$D$7:$D$37,"3") -> 7 | E46: WP 2-5 | F46: 1
B47: WP-4 | C47: =COUNTIFS(' Publicaciones año 2'!$D$7:$D$37,"4") -> 5 | E47: WP 4-5 | F47: 1
B48: WP-5 | C48: =COUNTIFS(' Publicaciones año 2'!$D$7:$D$37,"5") -> 1 | E48: WP 2-4-5 | F48: 2
B49: TOTAL | C49: =SUM(C44:C48) -> 23 | E49: TOTAL | F49: =SUM(F44:F48) -> 8
B52: Presupuesto Año 2 - 2024
B53: WP | C53: Ppto WP- 2024
B54: WP-1 | C54: 97219824
...

Sheet Publicaciones año 4-2026
J2: REGISTRO DE PUBLICACIONES
J4: INFORMADO A ANID - INFORME DE AVANCE NR. 4
J5: 2026
B7: Nr. | C7: Año Publicación | D7: WP | E7: WP consignado | F7: Nt pub con otros WP | G7: WOS Q1-Q4 (2024) | H7: Factor de impacto (2024) | I7: Top 10% | J7: Nombre publicación | K7: Autores | L7: Nro. Inst. Internacionales | M7: Publicación con Institución Internacional | N7: Nro. Inst. Nacionales | O7: Publicación con Institución Nacional | P7: Objetivo Directo/ Asociado CECAN (Identifíquelo Ej: WP-1 proyecto 1) | Q7: Funding % | R7: Estado de la Publicación | S7: Fecha estimada de publicación (En preparación/enviada) | T7: Invoice Nr. | U7: Fecha Invoice | V7: Revista | W7: Financiamiento CECAN | X7: Solicitud de apoyo solicitado por | Y7: Nr. Solicitud de apoyo | Z7: Valor Publicación revista | AA7: Valor $ pagado por UC | AB7: Valor $ pagado por UCH | AC7: 20000000 | AD7: 0 | AE7: Fecha de publicación | AF7: Volúmen. Pág. Inicio y final | AG7: DOI | AH7: ISSN | AI7: Nr. Productividad | AJ7: Link paper | AK7: Informado en Informe de Avance
B8: 50 | C8: 2025 | D8: 5-2 | E8: 10 | F8: 1 | G8: Q2 | H8: 4.4 | J8: Potential Impact of Compound Bayesian Inference in Medicine: Application to Colonoscopy Prioritization | K8: Pierre Collet 1,2,3,*, Felipe Quezada-Diaz 2,3 and Carla Taramasco 1,2,3 | L8: 0 | N8: 1 | O8: ITISB, Facultad de Ingeniería, Universidad Andres Bello, Viña del Mar, Chile 2520000, Chile; pierre.collet@ unab.cl, c1arla.taramasco@unab.cl 2 Unidad de Coloproctología. Servicio de Cirugía. Complejo Asistencial Doctor Sotero del Rio. Santiago 8550000, Chile; ffquezad@gmail.com 3 Centro para la Prevención y Control del Cáncer (CECAN) | T8: 3906851 | U8: 45964 | V8: Cancers | X8: Carla Taramasco | Y8: 14-2025 | Z8: USD 3255,52 | AA8: 3076890
B9: 49 | C9: 2025 | D9: 2 | E9: 2 | J9: Impact of a curriculum reform in graduate students self-reported palliative care competencies | K9: Mónica Grez A. MD (1) ; Alfredo Rodríguez-Nunez MD (1) ; Armando Maldonado-Morgado MD (1) ; Felipe Castro MD (2) ; Nicolás Orozco MD (2) ; Luciana Crispino MD (1) ; Francisca Villouta MD (1) ; Carolina Jaña MD(1) ; Ofelia Leiva-Vásquez MD (1) ; Pedro E. Pérez-Cruz MD MPH | L9: 0 | N9: 0 | O9: (1) Section of Palliative Medicine, School of Medicine, Pontificia Universidad Católica de Chile (UC|Chile), Santiago, Chile. (2) Students, School of Medicine, UC|Chile, Santiago, Chile. (3) Center for Cancer Prevention and Control (CECAN). | V9: Journal of Pain and Sumptom Management

Sheet  Publicaciones año 3
J2: REGISTRO DE PUBLICACIONES | AD2: ENVIAR PDF DE LA PUBLICACION A ccabrerav@uc.cl con copia a cgoicb@uc.cl y a cecan@uc.cl
J4: INFORMADO A ANID - INFORME DE AVANCE NR. 3
J5: 2025 | AD5: Los casilleros de este color deben ser llenados cuando la publicacion se haya relizado
D6: Completar para solicitud de financiamiento | AB6: Saldo UC | AC6: Saldo UCH | AD6: COMPLETAR CUANDO EL PAPER HA SIDO PUBLICADO
B7: Nr. | C7: Año Publicación | D7: WP | E7: WP consignado | F7: Nt pub con otros WP | G7: WOS Q1-Q4 (2024) | H7: Factor de impacto (2024) | I7: Top 10% | J7: Nombre publicación | K7: Autores | L7: Nro. Inst. Internacionales | M7: Publicación con Institución Internacional | N7: Nro. Inst. Nacionales | O7: Publicación con Institución Nacional | P7: Funding % | Q7: Estado de la Publicación | R7: Fecha estimada de publicación (En preparación/enviada) | S7: Invoice Nr. | T7: Fecha Invoice | U7: Revista | V7: Financiamiento CECAN | W7: Solicitud de apoyo solicitado por | X7: Nr. Solicitud de apoyo | Y7: Valor Publicación revista | Z7: Valor $ pagado por UC | AA7: Valor $ pagado por UCH | AB7: 20000000 | AC7: 0 | AD7: Fecha de publicación | AE7: Volúmen. Pág. Inicio y final | AF7: DOI | AG7: ISSN | AH7: Nr. Productividad | AI7: Link paper | AJ7: Informado en Informe de Avance
B8: 1 | C8: 2024 | D8: 3 | E8: 3 | G8: Q3 | H8: 1.5 | J8: Alpha-Lipoic Acid-Mediated Inhibition of LTB4 Synthesis Suppresses Epithelial-Mesenchymal Transition, Modulating Functional and Tumorigenic Capacities in Non-Small Cell Lung Cancer A549 Cells | K8: María José Torres, PhD, Juan Carlos Ríos, PhD ,Alexandra Valle, MSc , Sebastián Indo, PhD , Kevin Brockway GV, MSc, Fernanda López-Moncada, Mario Faúndez, PhD, Enrique A. Castellón, PhD, Héctor R. Contreras | L8: 0 | N8: 1 | O8: 1 Laboratorio de Farmacología y Toxicología Molecular. Escuela de Química y Farmacia. Facultad de Química y de Farmacia. Pontificia Universidad Católica de Chile, Santiago, Chile. 2 Programa de Farmacología y Toxicología. Facultad de Medicina. Pontificia Universidad Católica de Chile, Santiago, Chile. 3 Laboratorio de Oncología Celular y Molecular. Departamento de Oncología Básico-Clínica. Facultad de Medicina. Universidad de Chile, Santiago, Chile. 4 Departamento de Tecnología Médica. Facultad de Medicina. Universidad de Chile, Santiago, Chile. 5 Escuela de Tecnología Médica. Universidad Austral de Chile, Puerto Montt, Chile. 6 Centro para la Prevención y el Control del Cáncer (CECAN), Santiago, Chile. 7 Departamento de Laboratorios Clínicos. Facultad de Medicina. Pontificia Universidad Católica de Chile, Santiago, Chile. | P8: 100 | Q8: Publicado | S8: OAD0000507291 | T8: 45624 | U8: Current Therapeutic Research | V8: 1 | W8: Enrique Castellón | X8: 15-2024 | Y8: USD 2460 | Z8: =2460*972.43 -> 2392177.8 | AB8: Pagado con fondos 2024 | AD8: 45625 | AE8: Vol.102 | AF8: https://doi.org/10.1016/j.curtheres.2024.100765
B9: 2 | C9: 2024 | D9: 2-3 | E9: 10 | F9: 1 | G9: Q1 | H9: 4.6 | I9: 0 | J9: A snapshot of cancer in Chile II: an update on research, strategies and analytical frameworks for equity, innovation and national development | K9: Cristóbal Vacarezza, Julieta Araneda, Pamela Gonzalez, Oscar Arteaga, Katherine Marcelain, Enrique A Castellon, Ana Periera, Maroun Khoury, Bettina Müller, Juan Alberto Lecaros, Sofia P Salas, Arnoldo Riquelme, Alejandro H Corvalan, Jorge Jiménez de la Jara, Catterina Ferreccio, Carolina Goic, Bruno Nervi, Juan Carlos Roa, Gareth I Owen | L9: 0 | N9: 1 | O9: 1- Servicio de Salud del Reloncavi, Esmeralda 269, Puerto Montt, 2-Faculty of Health and Odontology, Universidad Diego Portales, Santiago, 3- Millennium Institute on Immunology and Immunotherapy, Santiago; 4-Institute of Nutrition and Food Technology (INTA), University of Chile, 5-Laboratory of Nano‑Regenerative Medicine, Faculty of Medicine, Universidad de Los Andes, Santiago; 6- IMPACT‑ Center of Interventional Medicine for Precision and Advanced Cellular Therapy, Universidad de Los Andes, Santiago, 7- Center for Bioethics,Faculty of Medicine, Clinica Alemana, Universidad del Desarrollo Santiago, 8- Chilean Cooperative Group for Oncological Research (GOCCHI), Santiago, 9- National Cancer Institute, Santiago, 10- Bioethics and Law Observatory, 11-Institute of Sciences and Innovation in Medicine, Universidad del Desarrollo, Santiago, 12- Advanced Center for Chronic Diseases (FONDAP‑ACCDiS), 13- National Cancer Commission, Santiago | P9: 100 | Q9: Publicado | S9: 1452808303 | T9: 45577 | U9: Biological Research | V9: 1 | W9: Gareth Owen | X9: 16-2024 | Y9: USD 2307 | Z9: =2307*975.67 -> 2250870.7 | AB9: Pagado con fondos 2024 | AD9: 45644 | AF9: https://doi.org/10.1186/s40659-024-00574-2
B10: 3 | C10: 2024 | D10: 2-3 | E10: 10 | F10: 1 | G10: Q2 | H10: 4.4 | J10: Inbreeding and Gallbladder Cancer Risk: Homozygosity Associations Adjusted for Indigenous American Ancestry, BMI, and Genetic Risk of Gallstone Disease | K10: Francisco Ceballos 1,2,* , Felix Boekstegers 1 Katherine Marcelain 3 , Dominique Scherer 1 , Carol Barahona Ponce 1 , Valentina Gárate-Calderón 1,3, Melanie Waldenberger 4 , , Erik Morales 5,6, Armando Rojas 6 , César Munoz 5,6, Javier Retamales 7 Olga Barajas 3,10, María Teresa Rivera 11 , Gonzalo de Toro 8,9 , Allan Vera Kortmann 8 , , Analía Cortés 11, Denisse Loader 12, Javiera Saavedra 12, Lorena Gutiérrez 13, Alejandro Ortega 14, Maria Enriqueta Bertrán 15, Leonardo Bartolotti 16, Fernando Gabler 17, Mónica Campos 17, Juan Alvarado 18, Fabricio Moisán 18, Loreto Spencer 18, Bruno Nervi 19 , Daniel Carvajal-Hausdorf 20, Héctor Losada 21 Pamela Salinas 25 , Mauricio Almau 22, Plinio Fernández 22, Jordi Olloquequi 23,24 andJustoLorenzoBermejo 1,26, | L10: 1 | M10: 1 Statistical Genetics Research Group, Institute of Medical Biometry, Heidelberg University, Im Neuenheimer Feld 130.3, 69120 Heidelberg, Germany; boekstegers@imbi.uni-heidelberg.de (F.B.); scherer@imbi.uni-heidelberg.de (D.S.); barahona@imbi.uni-heidelberg.de (C.B.P.); garate@imbi.uni-heidelberg.de (V.G.-C.) 2 Health Institute Carlos III (ISCIII), 28029 Madrid, Spain 3 Department of Basic and Clinical Oncology, Center for Cancer Prevention and Control (CECAN), Medical Faculty, University of Chile, Santiago 380000, Chile; kmarcelain@uchile.cl (K.M.); obarajas@hcuch.cl (O.B.) 4 Research Unit of Molecular Epidemiology and Institute of Epidemiology, Helmholtz Zentrum München, German Research Center for Environmental Health, 85764 Neuherberg, Germany; waldenberger@helmholtz-muenchen.de 5 Hospital Regional de Talca, Talca 3460000, Chile; emoralesm@hospitaldetalca.cl (E.M.); cmunozc@hospitaldetalca.cl (C.M.) 6 Facultad de Medicina, Universidad Católica del Maule, Talca 3460000, Chile; arojasr@ucm.cl 7 Instituto Nacional del Cáncer, Santiago 7500650, Chile; jretamales@gocchi.org 8 Hospital de Puerto Montt, Puerto Montt 5480000, Chile; gonzalo.detoro@uach.cl (G.d.T.); allan.vera@araucanianorte.cl (A.V.K.) 9 Escuela de Tecnología Médica, Universidad Austral de Chile sede Puerto Montt, Puerto Montt 5480000, Chile 10 Hospital Clínico Universidad de Chile, Santiago 8380456, Chile 11 Hospital del Salvador, Santiago 7500922, Chile; mrivera@hsalvador.cl (M.T.R.); acortes@hsalvador.cl (A.C.) 12 Hospital Padre Hurtado, Santiago 8880456, Chile; dloader@hurtadohosp.cl (D.L.); javiera.saavedra@hurtadohosp.cl (J.S.) 13 Hospital San Juan de Dios, Santiago 8320000, Chile; lorenaf.gutierrez@redsalud.gob.cl 14 Hospital Regional, Arica 1000000, Chile; alejandro.ortega@hjnc.cl 15 Unidad Registro Hospitalario de Cáncer, Hospital Base de Valdivia, Valdivia 5090146, Chile; enriqueta.bertran@redsalud.gov.cl 16 Hospital Base de Valdivia, Valdivia 5090146, Chile; leonardo.bartolotti@redsalud.gob.cl 17 Hospital San Borja Arriarán, Santiago 8320000, Chile; gablerf@uchile.cl (F.G.); monicam.camposm@redsalud.gob.cl (M.C.) 18 Hospital Regional Guillermo Grant Benavente, Concepción 4070386, Chile; jualvarado@udec.cl (J.A.); fabriziomoisan@udec.cl (F.M.); mspencer@udec.cl (L.S.) 19 Department of Hematology and Oncology, Center for Cancer Prevention and Control (CECAN), School of Medicine, Pontificia Universidad Católica de Chile, Santiago 8330077, Chile; bnervi@uc.cl 20 Facultad de Medicina, Clínica Alemana Universidad del Desarrollo, Santiago 7650568, Chile; carvajalh.daniel@gmail.com 21 Departamento de Cirugía, Universidad de La Frontera, Temuco 4780000, Chile; hector.losada@ufrontera.cl 22 Hospital de Rancagua, Rancagua 2820000, Chile; halmau@clinicaisamedica.cl (M.A.); pfernandez@clinicaisamedica.cl (P.F.) 23 Department of Biochemistry and Physiology, Faculty of Pharmacy and Food Sciences, University of Barcelona, 08007 Barcelona, Spain; jordiolloquequi@ub.edu 24 Facultad de Ciencias de la Salud, Universidad Autónoma de Chile, Talca 3460000, Chile 25 Instituto de Alta Investigación, Tarapacá University, Arica 1000000, Chile; psalinas@gestion.uta.cl 26 Laboratory of Biostatistics for Precision Oncology, Institut de Cancérologie Strasbourg Europe, 67200 Strasbourg, France | N10: 1 | O10: 1 Statistical Genetics Research Group, Institute of Medical Biometry, Heidelberg University, Im Neuenheimer Feld 130.3, 69120 Heidelberg, Germany; boekstegers@imbi.uni-heidelberg.de (F.B.); scherer@imbi.uni-heidelberg.de (D.S.); barahona@imbi.uni-heidelberg.de (C.B.P.); garate@imbi.uni-heidelberg.de (V.G.-C.) 2 Health Institute Carlos III (ISCIII), 28029 Madrid, Spain 3 Department of Basic and Clinical Oncology, Center for Cancer Prevention and Control (CECAN), Medical Faculty, University of Chile, Santiago 380000, Chile; kmarcelain@uchile.cl (K.M.); obarajas@hcuch.cl (O.B.) 4 Research Unit of Molecular Epidemiology and Institute of Epidemiology, Helmholtz Zentrum München, German Research Center for Environmental Health, 85764 Neuherberg, Germany; waldenberger@helmholtz-muenchen.de 5 Hospital Regional de Talca, Talca 3460000, Chile; emoralesm@hospitaldetalca.cl (E.M.); cmunozc@hospitaldetalca.cl (C.M.) 6 Facultad de Medicina, Universidad Católica del Maule, Talca 3460000, Chile; arojasr@ucm.cl 7 Instituto Nacional del Cáncer, Santiago 7500650, Chile; jretamales@gocchi.org 8 Hospital de Puerto Montt, Puerto Montt 5480000, Chile; gonzalo.detoro@uach.cl (G.d.T.); allan.vera@araucanianorte.cl (A.V.K.) 9 Escuela de Tecnología Médica, Universidad Austral de Chile sede Puerto Montt, Puerto Montt 5480000, Chile 10 Hospital Clínico Universidad de Chile, Santiago 8380456, Chile 11 Hospital del Salvador, Santiago 7500922, Chile; mrivera@hsalvador.cl (M.T.R.); acortes@hsalvador.cl (A.C.) 12 Hospital Padre Hurtado, Santiago 8880456, Chile; dloader@hurtadohosp.cl (D.L.); javiera.saavedra@hurtadohosp.cl (J.S.) 13 Hospital San Juan de Dios, Santiago 8320000, Chile; lorenaf.gutierrez@redsalud.gob.cl 14 Hospital Regional, Arica 1000000, Chile; alejandro.ortega@hjnc.cl 15 Unidad Registro Hospitalario de Cáncer, Hospital Base de Valdivia, Valdivia 5090146, Chile; enriqueta.bertran@redsalud.gov.cl 16 Hospital Base de Valdivia, Valdivia 5090146, Chile; leonardo.bartolotti@redsalud.gob.cl 17 Hospital San Borja Arriarán, Santiago 8320000, Chile; gablerf@uchile.cl (F.G.); monicam.camposm@redsalud.gob.cl (M.C.) 18 Hospital Regional Guillermo Grant Benavente, Concepción 4070386, Chile; jualvarado@udec.cl (J.A.); fabriziomoisan@udec.cl (F.M.); mspencer@udec.cl (L.S.) 19 Department of Hematology and Oncology, Center for Cancer Prevention and Control (CECAN), School of Medicine, Pontificia Universidad Católica de Chile, Santiago 8330077, Chile; bnervi@uc.cl 20 Facultad de Medicina, Clínica Alemana Universidad del Desarrollo, Santiago 7650568, Chile; carvajalh.daniel@gmail.com 21 Departamento de Cirugía, Universidad de La Frontera, Temuco 4780000, Chile; hector.losada@ufrontera.cl 22 Hospital de Rancagua, Rancagua 2820000, Chile; halmau@clinicaisamedica.cl (M.A.); pfernandez@clinicaisamedica.cl (P.F.) 23 Department of Biochemistry and Physiology, Faculty of Pharmacy and Food Sciences, University of Barcelona, 08007 Barcelona, Spain; jordiolloquequi@ub.edu 24 Facultad de Ciencias de la Salud, Universidad Autónoma de Chile, Talca 3460000, Chile 25 Instituto de Alta Investigación, Tarapacá University, Arica 1000000, Chile; psalinas@gestion.uta.cl 26 Laboratory of Biostatistics for Precision Oncology, Institut de Cancérologie Strasbourg Europe, 67200 Strasbourg, France | Q10: Publicado | U10: Cancers | V10: 0 | W10: No | AD10: 45643 | AF10: https://doi.org/10.3390/cancers16244195
B11: 4 | C11: 2025 | D11: 4 | E11: 4 | G11: Q1 | H11: 3.6 | I11: 1 | J11: Perceived barriers to reaching equity in effective access to diagnosis and treatment for women with breast cancer in Chile | K11: Campaña, C, Cabieses, B, Obach, A, Vezzani, F | L11: 0 | N11: 0 | P11: 100 | Q11: Publicado | S11: 1452824357 | T11: 45717 | U11: Humanities and Social Sciences Communications | V11: 1 | W11: Báltica Cabieses | X11: 17-2024 | Y11: USD 1765 | Z11: =1765*1007.51 -> 1778255.1 | AB11: Pagado con fondos 2024 | AD11: 45693 | AF11: https://doi.org/10.1057/s41599-024-04259-9
B12: 5 | C12: 2025 | D12: 2-3 | E12: 10 | F12: 1 | G12: Q1 | H12: 5.1 | I12: 0 | J12: Comprehensive histopathological analysis of gastric cancer in European and Latin America populations reveals differences in PDL1, HER2, p53 and MUC6 expression | K12: Carolina Martínez‑Ciarpaglini1 · Rita Barros2,3,4,5 · Carmelo Caballero6 · Hugo Boggino6 · Lorena Alarcón‑Molero1,7 · Bárbara Peleteiro8,9,10,11 · Erika Ruiz‑García12,13 · Edith Fernandez‑Figueroa14 · Roberto Herrera‑Goepfert15 · Consuelo Díaz‑Romero16 · Rui Ferreira2,17 · Tessa S. Groen‑van Schooten18,19,20 · Cinthia Gauna21 · Rita Pereira21 · Daniel Cantero22 · Horacio Lezcano23 · Federico Esteso24 · Juan O´Connor24 · Arnoldo Riquelme25 · Gareth I. Owen26 · Marcelo Garrido27 · Juan Carlos Roa28 · Fiorella Ruiz‑Pace29 · Ana Vivancos30 · Marc Diez‑García31 · Maria Alsina31,32 · Judit Matito30 · Agatha Martin30 · Marina Gómez30 · Ester Castillo30 · Maria Vila30 · João Santos‑Antunes33 · Andreia Costa34 · Florian Lordick35 · Judith Farrés36 · Brenda Palomar‑De Lucas37 · Manuel Cabeza‑Segura37 · Rosanna Villagrasa38 · Elena Jimenez‑Martí37 · Ana Miralles‑Marco37 · Rodrigo Dienstmann29 · Sarah Derks18,19,20 · Ceu Figueiredo2,3,4 · Andrés Cervantes37,38,39 · Fátima Carneiro2,3,4,5 · Tania Fleitas‑Kanonnikoff37 | L12: 1 | M12: 1 Department of Pathology, Hospital Clinico Universitario, INCLIVA, Biomedical Research Institute, University of Valencia, Valencia, Spain 2 Ipatimup, Institute of Molecular Pathology and Immunology of the University of Porto, Rua Júlio Amaral de Carvalho 45, 4200 ‑135 Porto, Portugal 3 i3S‑Instituto de Investigação e Inovação em Saúde, Universidade Do Porto, Porto, Portugal 4 Faculty of Medicine of the University of Porto, Porto, Portugal 5 Department of Pathology, Unidade Local de Saúde São João, Porto, Portugal 6 Department of Pathology, GENPAT, Asunción, Paraguay 7 Department of Pathology, Hospital General de Valdepeñas, Valdepeñas, Spain 8 Hospital Epidemiology Center, University Hospital Center of São João, Porto, Portugal 9 Department of Public Health and Forensic Sciences, and Medical Education, Faculty of Medicine, University of Porto, Porto, Portugal 10 EPIUnit‑Institute of Public Health, University of Porto, Porto, Portugal 11 Laboratory for Integrative and Translational Research in Population Health (ITR), University of Porto, Porto, Portugal 12 Departamento de Tumores de Tubo Digestivo, Instituto Nacional de Cancerología, Mexico City, México 13 Laboratorio de Medicina Traslacional, Instituto Nacional de Cancerología, Mexico City, México 14 Núcleo B de Innovación en Medicina de Precisión, Instituto Nacional de Medicina Genómica, Mexico City, México 15 Departamento de Patología Quirúrgica, Instituto Nacional de Cancerología, Mexico City, México 16 Departamento de Oncología Médica, Instituto Nacional de Cancerología, Mexico City, México 17 Microbes & Cancer. i3S, Instituto de Investigação e Inovação em Saúde, , Rua Alfredo Allen, 208, 4200‑135 Porto, Portugal 18 Department of Medical Oncology, Amsterdam University Medical Center (UMC) Location Vrije Universiteit Amsterdam, Amsterdam, Netherlands 19 Cancer Biology and Immunology, Cancer Center Amsterdam, Amsterdam, Netherlands 20 Oncode Institute, Amsterdam, The Netherlands 21 Medical Oncology Department, Instituto de Previsión Social, Asunción, Paraguay 22 Department of Gastroenterology, Instituto de Previsión, Social, Asunción, Paraguay 23 Pathology Department, Instituto de Previsión Social, Asunción, Paraguay 24Oncology Data Science, Valld`Hebron Institute of Oncology, Barcelona, Spain 30 Cancer Genomics Lab, Valld`Hebron Institute of Oncology, Barcelona, Spain 31 Medical Oncology Department, Valld`Hebron Institute of Oncology, Barcelona, Spain 32 Hospital Universitario de Navarra, Navarrabiomed-IdiSNA, Pamplona, Spain 33 Department of Gastroenterology, Unidade Local de Saúde São João, Porto, Portugal 34 Department of Oncology, Unidade Local de Saúde São João, Porto, Portugal 35 Department of Medicine (Oncology, Gastroenterology, Hepatology, and Pulmonology), Comprehensive Cancer Center Central Germany (CCCG), University of Leipzig Medical Center, Leipzig, Germany 36 Anaxomics Biotech, S.L. Barcelona, Barcelona, Spain 37 Department of Medical Oncology, Hospital Clinico Universitario, INCLIVA, Biomedical Research Institute, University of Valencia, Avenida Menendez Pelayo nro 4 accesorio, Valencia, Spain 38 Department of Gastroenterology, Hospital Clínico Universitario de Valencia, Valencia, Spain 39 CiberOnc. Carlos III Institute, Madrid, Spain Medical Oncology Department, Instituto Alexander Fleming, Buenos Aires, Argentina | N12: 1 | O12: Centro de Oncología de Precisión, Universidad Mayor, Santiago, Chile | Q12: Publicado | S12: 0 | U12: Gastric Cancer | V12: 0 | W12: No | Y12: 0 | AD12: 45662 | AF12: https://doi.org/10.1007/s10120-024-01578-3
B13: 6 | C13: 2025 | D13: 3 | E13: 3 | G13: Q1 | H13: 4.9 | I13: 0 | J13: Understanding microRNA-mediated chemoresistance in colorectal cancer treatment | K13: Guillermo Valenzuela; Héctor R. Contreras; Katherine Marcelain; Mauricio Burotto; Jaime González-Montero | L13: 0 | N13: 1 | O13: Bradford Hill Clinical Research Center | P13: 100 | Q13: Publicado | S13: 3432801 | T13: 45684 | U13: Int.J.Molecular Sciences | V13: 1 | W13: Jaime González | X13: 1-2025 | Y13: USD 2557,46 | Z13: 2369538 | AB13: Pagado con fondos 2024 | AD13: 29-02-2025 | AF13: https://doi.org/10.3390/ijms26031168
B14: 7 | C14: 2025 | D14: 1 | E14: 1 | G14: Q1 | H14: 3.4 | I14: 0 | J14: Exposure to pesticides in Chile and its relationship with carcinogenic potential: a review | K14: María Teresa Muñoz Quezada, Veronica Iglesias, Liliana Zúñiga, Floria Pancetti, Claudia Foerster, Natalia Landeros, Boris Lucero, Daniel Schwantes, Sandra Cortés | L14: 0 | N14: 1 | O14: Laboratorio de Neurotoxicología Ambiental, Departamento de Ciencias Biomédicas, Facultad de Medicina, Universidad Católica del Norte, Coquimbo, Chile, 6 Centro de Investigación y Desarrollo Tecnológico en Algas y otros Recursos Biológicos (CIDTA), Universidad Católica del Norte, Coquimbo, Chile, 7 Institute of Agri-food, Animal and Environmental Sciences (ICA3), Universidad de O' Higgins, San Fernando, Chile, 8 Unidad de Innovación en Prevención y Oncología de Precisión, Centro Oncológico, Facultad de Medicina, Universidad Católica del Maule, Talca, Chile, 9 In Vivo Tumor Biology Research Facility, Centro Oncológico, Facultad de Medicina, Universidad Católica del Maule, Talca, Chile, 10 The Neuropsychology and Cognitive Neurosciences Research Center CINPSI Neurocog, Faculty of Health Sciences, Universidad Católica del Maule, Talca, Advanced Center for Chronic Diseases (ACCDiS), Centro de Desarrollo Urbano Sustentable (CEDEUS), Santiago | P14: 50 | Q14: Publicado | U14: Frontiers in Public Health | V14: 0.5 | W14: M. Teresa Muñoz | X14: 2-2025 | Y14: USD 3495/2 | Z14: 1619094 | AB14: Pagado con fondos 2024 | AD14: 45748 | AF14: https://doi: 10.3389/fpubh.2025.1531751
B15: 8 | C15: 2025 | D15: 3 | E15: 3 | G15: Q2 | H15: 4.4 | J15: Patient-Derived Organoid Models for NKT Cell-Based Cancer Immunotherapy | K15: Pablo A. Palacios 1,† , Iván Flores 2,†, Lucas Cereceda 1 , Francisco F. Otero 1, Marioly Müller 3, Priscilla Brebi 4,5 , Héctor R. Contreras 2,6,* and Leandro J. Carreño 1,5,* | L15: 0 | N15: 1 | O15: Millennium Institute on Immunology and Immunotherapy, Laboratory of Integrative Biology (LIBi), Centro de Excelencia en Medicina Traslacional (CEMT), Scientific and Technological Bioresource Nucleus (BIOREN), Universidad de La Frontera, Temuco 4811230, Chile, Biomedical Research Consortium (BMRC), Santiago | P15: 30 | Q15: Publicado | U15: Cancers | V15: 0 | W15: No | AD15: 45683 | AF15: https://doi.org/10.3390/ cancers17030406
B16: 9 | C16: 2025 | D16: 4 | E16: 4 | G16: Q3 | H16: 2 | J16: Sociodemographic, political, and policy contexts of cancer care: A comparative analysis of countries with the highest survival rates | K16: Alejandra Fuentes-García, Carla Flores-Figueroa, Alondra Castillo-Delgado | L16: 0 | N16: 1 | O16: School of Nursing, Faculty of Health, Universidad Santo Tom´as, Chile d School of Speech Therapy, Faculty of Medicine, Universidad de Valparaíso, | P16: 100 | Q16: Publicado | U16: Journal of Cancer Policy | V16: 0 | W16: No | AD16: 45688 | AF16: https://doi.org/10.1016/j.jcpo.2025.100559
B17: 10 | C17: 2025 | D17: 2 | E17: 2 | G17: Q1 | H17: 8.1 | I17: 1 | J17: ACG Clinical Guideline: Diagnosis and Management of Gastric Premalignant Conditions | K17: Douglas R. Morgan, MD, MPH, FACG1, Juan E. Corral, MD,MPH2, Dan Li,MD3,4, Elizabeth A. Montgomery,MD5, Arnoldo Riquelme,MD6, John J. Kim, MD, FACG7, Bryan Sauer, MD, MSc, FACG8 and Shailja C. Shah, MD, MPH9,10 | L17: 1 | M17: 1Division of Gastroenterology, The University of Alabama at Birmingham, Birmingham, Alabama, USA; 2Division of Gastroenterology, Prisma Health, Greenville, South Carolina, USA; 3Department of Gastroenterology, Kaiser Permanente Medical Center, Santa Clara, California, USA; 4Kaiser Permanente Northern California Division of Research, Oakland, California, USA; 5Department of Pathology, University of Miami Miller School of Medicine, Miami, Florida, USA, 7Division of Gastroenterology, Los Angeles General Medical Center, Los Angeles, California, USA; 8Division of Gastroenterology, University of Virginia, Charlottesville, Virginia, USA; 9Division of Gastroenterology, University of California, San Diego, La Jolla, California, USA; 10Gastroenterology Section, Jennifer Moreno Veterans Affairs Medical Center, La Jolla, California, USA. | N17: 0 | P17: 50 | Q17: Publicado | U17: Amer J. of Gastroenterology | V17: 0 | W17: No | AD17: 45728 | AF17: http://links.lww.com/AJG/D558, http://links.lww.com/AJG/D559
B18: 11 | C18: 2025 | D18: 2 | E18: 2 | G18: Q3 | H18: 2.1 | J18: Accurate prognostic awareness is associated with increased emotional distress in Latino patients with advanced cancer | K18: Pedro E. Pérez-Cruz, M.D., M.P.H.1,2 , María Jesús San Martín, M.PSYCH.3, Josefa Palacios, M.SC., PH.D.4 , Laura Tupper-Satt, M.D.5, Marcela González-Otaíza, M.D.5 and Paula Repetto, PH.D.2,6 | L18: 0 | N18: 1 | O18: 3Escuela de Psicología, Facultad de Educación, Psicología y Familia, Universidad Finis Terrae, 5Unidad de Cuidados Paliativos, Complejo Asistencial Dr. Sótero del Río, Servicio de Salud Metropolitano Sur Oriente, Puente Alto, | Q18: Publicado | U18: Palliative and Supportive Care | V18: 0 | W18: No | AD18: 45769 | AF18: https://doi.org/ 10.1017/S1478951525000252
B19: 12 | C19: 2025 | D19: 5-2 | E19: 10 | F19: 1 | G19: Q2 | H19: 3 | J19: Education and Symptom Reporting in an mHealth App for Patients With Cancer: Mixed Methods Development and Validation Study | K19: Carolina Muñoz Olivar1,2*, MSc; Miguel Pineiro2,3*, PhD; Juan Sebastián Gómez Quintero4*, PhD; Carlos Javier Avendaño-Vásquez5,6*, PhD; Pablo Ormeño-Arriagada7*, PhD; Silvia Palma Rivadeneira2,8,9*, MSc; Carla Taramasco Toro2,3*, PhD | L19: 1 | M19: Faculty of Medicine, Antonio Nariño University, Bogotá, Colombia; 6School of Nursing, Industrial University of Santander, Bucaramanga, Colombia | N19: 1 | O19: 7Faculty of Engineering, Business, and Agro-Environmental Sciences, Department of Computer Civil Engineering, Universidad Viña del Mar, Viña del Mar, Chile; 9UC-CHRISTUS Health Network, Santiago, Chile | P19: 100 | Q19: Publicado | U19: JMIR Human Factors | V19: 1 | W19: Carla Taramasco | X19: 3-2025 | Y19: USD 2123,95 | Z19: 1967882 | AB19: Pagado con fondos 2024 | AD19: 45775 | AF19: doi:10.2196/60169
B20: 13 | C20: 2025 | D20: 5 | E20: 5 | G20: Q2 | H20: 1.3 | J20: Using implementation science to develop and deploy an oncology electronic health record | K20: Carla Taramasco, René Noel, Gastón Márquez, Diego Robles | L20: 0 | N20: 1 | O20: Escuela de Ingeniería Informática, Universidad de Valparaíso, Departamento de Ciencias de la Computación y Tecnologías de la Información, Universidad del Bío-Bío, Chillán; Escuela de Kinesiología. Facultad de Odontología y Salud, Universidad Diego Portales, Santiago | P20: 100 | Q20: Publicado | U20: Informatics in Medicine | V20: 0 | W20: Carla Taramasco | X20: 4-2025 | Y20: 0 | AD20: 45698 | AF20: https://doi.org/10.1016/j.imu.2025.101625
B21: 14 | C21: 2025 | D21: 2 | E21: 2 | G21: Q2 | H21: 2.3 | J21: Spiritual care for prevention of psychological disorders in critically ill patients: study protocol of a feasibility randomised controlled pilot trial | K21: Paula Repetto1,2, Carolina Ruiz3,4, Verónica Rojas5, Patricia Olivares6,7, Jan Bakker8, Leyla Alegria3,9 | L21: 1 | M21: 8Department of Intensive Care Adults, Erasmus MC University Medical Center, Rotterdam, The Netherlands | N21: 1 | O21: 4Unidad de Paciente Critico, Complejo Asistencial Dr Sotero del Río, Santiago, Servicio de Medicina Interna, Complejo Asistencial Dr Sotero del Río, Santiago, Chile; | Q21: Publicado | U21: BMJ Open | V21: 0 | W21: Paula Repetto | X21: 5-2025 | AD21: 45750 | AF21: https://doi.org/10.1136/bmjopen-2024-084914
B22: 15 | C22: 2025 | D22: 1 | E22: 1 | G22: Q2 | H22: 2.7 | J22: Assessing the alignment of Chilean Food-Based Dietary Guidelines on cancer prevention: a content analysis | K22: Alejandra Ortega Guzmán, Solange Parra-Soto, María Jesús Vega-Salas, Lorena Rodríguez-Osiac, Sandra López-Arana | L22: 0 | N22: 1 | O22: Centro para la Transversalización de Género en I+D+i+e, Vicerrectoría de Investigación y Doctorados, Universidad Autónoma de Chile, Santiago, 2 Department of Nutrition and Public Health, Faculty of Health and Food Science, Universidad del Bío-Bío, Chillan, Escuela de Nutrición y Dietética, Facultad de Medicina, Universidad Finis Terrae, Providencia | P22: 100 | Q22: Publicado | U22: Healthcare | V22: 1 | W22: Lorena Rodriguez | X22: 6-2025 | Y22: USD 3304,47 | Z22: 3176058 | AB22: Pagado con fondos 2024 | AD22: 45790 | AF22: https://doi.org/10.3390/healthcare13101133
B23: 16 | C23: 2025 | D23: 4 | E23: 4 | G23: Q2 | H23: 3 | J23: Barriers to accessing formal cancer care from the perspective of informal caregivers: a qualitative study | K23: Carla Campaña1,2 · Báltica Cabieses1,2 · Alexandra Obach1,2 · Francisca Vezzani1,2 · Angela Estay3 · Diego Carrillo4 | L23: 0 | N23: 1 | O23: Centro Oncológico del Norte, Antofagasta, Chile | P23: 100 | Q23: Publicado | U23: Supportive Care in Cancer | V23: 1 | W23: Carla Campaña | X23: 7-2025 | Y23: USD 4765 | Z23: 4468665 | AB23: Pagado con fondos 2024 | AD23: 45768 | AF23: https://doi.org/10.1007/s00520-025-09426-5
B24: 17 | C24: 2025 | D24: 4 | E24: 4 | G24: Q2 | H24: 2.6 | J24: Exploring the Characteristics of Cancer-Centred Civil Society Organisations in Chile: A Qualitative Study | K24: Antonia Roberts1,4, Francisca Vezzani 1,4, Báltica Cabieses 1,2,4, Alexandra Obach1,4, Carla Campaña 1,4, Manuel A. Espinoza 3,4. | L24: 1 | M24: Department of Health Sciences, University of York, United Kingdom | N24: 0 | P24: 100 | Q24: Publicado | S24: PAB392735 | T24: 45771 | U24: PLOS One | V24: 1 | W24: Antonia Roberts | X24: 8-2025 | Y24: USD 2290 | Z24: 2137165 | AB24: =AB7-Z24 -> 17862835 | AD24: 45793 | AF24: https://doi.org/10.1371/journal.pone.0315589
B25: 18 | C25: 2025 | D25: 4-2 | E25: 10 | F25: 1 | G25: Q3 | H25: 1.5 | J25: Utility Values of Health Status in Gastric Cancer: A Systematic Review | K25: Cristian González, Manuel Espinoza, Matías Libuy, Francisca Crispi, ARNOLDO RIQUELME, Fernando Alarid-Escudero, Gonzalo Latorre, Margarita Pizarro, Cristóbal Cuadrado | L25: 1 | M25: Department of Health Policy, School of Medicine and Center for Health Policy, Freeman Spogli Institute, Stanford University, Stanford, CA, USA | N25: 0 | Q25: Publicado | U25: Value in Health Reg Issues | V25: 0 | W25: No | Z25: 0 | AB25: =AB24-Z25 -> 17862835 | AD25: 45686 | AF25: https://doi.org/10.1016/j.vhri.2024.101063
B26: 19 | C26: 2025 | D26: 2 | E26: 2 | G26: Q3 | H26: 1.3 | J26: Implementation of an Educational Intervention for Gastric Cancer Awareness in the General Population in CELAC and Europe: A Strategy Proposed by the LEGACy Consortium | K26: Juan Antonio Carbonell‑Asins1 · Elena Jiménez‑Martí2,3 · Sergio Romero2 · Eduardo García4 · Ana Miralles‑Marco2 · Beatriz Lopez2 · Marisol Huerta2 · Carmelo Caballero5 · Hugo Boggino5 ·Cinthia Gauna6 · Olga Beatriz Acevedo‑Funes7 · Gabriel Benitez Nuñez7 · Claudia Melina Céspedes‑Cardozo7 ·Edith A. Fernandez‑Figueroa8 · Nayeli Ortiz‑Olvera9 · Erika Ruiz‑García10,11 · Fátima Carneiro12,13,14 ·Rita Barros12,13,14 · Ceu Figueiredo4,12,13 · Rui M. Ferreira12,13 · Tessa Suzanne Groen ‑ van Schooten15,16,17 ·Demi van Santvliet15 · Sarah Derks15,16,17 · Romina Luca18 · Maria Alsina19 · Arnoldo Riquelme20,21 · Andrés Cervantes2,22 · Tania Fleitas2 | L26: 1 | M26: 1 Department of Medical Oncology, Hospital Clínico Universitario, Biostatistical Unit, INCLIVA, Biomedical Research Institute, Avenida Menendez Pelayo Nro 4 Accesorio, 46010 Valencia, Spain 2 Department of Medical Oncology Hospital Clínico Universitario, INCLIVA, Biomedical Research Institute, University of Valencia, Avenida Blasco Ibañez 17, 46010 Valencia, Spain 3 Department of Biochemistry, University of Valencia, Avenida Blasco Ibañez XX, 46010 Valencia, Spain 4 Vall d Hebron Institute of Oncology, Biostatistical Unit, Calle Nazaret 155‑177 08035, Barcelona, Spain 5 Genpat. Pathology Department, Guido Spano 1448, Asunción, Paraguay 6 Oncology Department, Instituto de Previsión Social, Av Santisimo Sacramento y Dr. Manuel Peña, Asunción, Paraguay 7 Cátedra de Biofísica, Universidad Nacional de Asunción, Campus Universitario San Lorenzo, San Lorenzo, Paraguay 8 Núcleo B de Innovación en Medicina de Precisión, Instituto Nacional de Medicina Genómica, Periferico Sur Número 4809, Colonia Arenal, Tepepán, Alcaldia Tialpan, 14610 Ciudad de México, Mexico 9 Departamento de Gastroenterología, UMAE, Hospital de Especialidades Dr. Bernardo Sepúlveda, Centro Médico Nacional Siglo XXI, IMSS, Avda Cuauhtemoc 330, Doctores, Cuauhtemoc, 06720 Ciudad de México, Mexico 10 Departamento de Tumores de Tubo Digestivo, Instituto Nacional de Cancerología, Avda San Fernando 22, Belisario Dominguez, Secc 16, Tialpán, 14080 Ciudad de México, Mexico 11 Laboratorio de Medicina Traslacional, Instituto Nacional de Cancerología, Avda San Fernando 22, Belisario Dominguez, Secc 16, Tialpán, 14080 Ciudad de México, Mexico 12 Institute of Molecular Pathology and Immunology of the University of Porto (IPATIMUP), Rua Julio Amaral de Carvalho, 45, 4200‑135 Porto, Portugal 13 i3S–Instituto de Investigação e Inovação em Saúde, Universidade Do Porto, R. Alfredo Allen 208, 4200‑135 Porto, Portugal 14 Department of Pathology, Faculty of Medicine of the University of Porto, Alameida Prof. Hernani Monteiro, 4200‑319 Porto, Portugal 15 Department of Medical Oncology, Amsterdam UMC Location University of Amsterdam, Meibergdreef 9, Amsterdam, The Netherlands 16 Cancer Center Amsterdam, Cancer Biology and Immunology, Meibergdreef 9, Amsterdam, The Netherlands 17 Oncode Institute, Jaarbeursplein 6, 3521 AL Utrecht, The Netherlands 18 Oncology Department, Instituto Alexander Flemming, Crammer 1180, C1426 Buenos Aires, Argentina 19 Oncology Department, Vall d Hebron Institute of Oncology, Calle Nazareth 115‑117, 08035 Barcelona, Spain 20 Gastroenterology Department, Pontificia Universidad Católica de Chile, Santiago, Chile 21 Centro Para La Prevención y Control del Cáncer (CECAN), Avenida Libertador Bernardo O`Higgins 340, Santiago de Chile, Chile 22 CIBERONC, Instituto de Salud Carlos III, Avenida de Monforte de Lemos 5, Fuencarral‑El Pardo, 28029 Madrid, Spain | N26: 0 | Q26: Publicado | U26: Journal of Cancer Education | V26: 0 | W26: No | Z26: 0 | AB26: =AB25-Z26 -> 17862835 | AD26: 45701 | AF26: https://doi.org/10.1007/s13187-025-02578-2
B27: 20 | C27: 2025 | D27: 2 | E27: 2 | G27: Q1 | H27: 25.9 | I27: 1 | J27: Innovation Meets Practice: A Scalable Simulation-based Methodology for Massive Paracentesis Training | K27: Úrsula Figueroa,1,* Cristián Jarry,1,* Martin Inzunza,1 Isabella Montero,1 Francisco Garrido,2 Ignacio Villagrán,3 Francisca Belmar,1 Gabriel Escalona,1 Arnoldo Riquelme,4,5 and Julián Varas | L27: 0 | N27: 1 | O27: UC Christus | Q27: Publicado | U27: Gastroenterology | V27: 0 | W27: No | Z27: 0 | AB27: =AB26-Z27 -> 17862835 | AD27: 45716 | AF27: https://doi.org/10.1053/j.gastro.2024.12.015
B28: 21 | C28: 2025 | D28: 2 | E28: 2 | G28: Q1 | H28: 4.3 | I28: 0 | J28: Helicobacter pylori and Colorectal Cancer: Meeting Sir Austin Bradford Hill's Causality Criteria | K28: Juan Sebastián Frías-Ordoñez 1 2 3 4, Arnoldo Riquelme 5 6, Hernando Marulanda-Fernandez 3 7 8, Lina Otero-Parra 3, José Augusto Urrego 1 2, Elder Otero-Ramos 3 5, José Darío Portillo-Miño 8 9, William Otero Regino 1 2 3 8 | L28: 1 | M28: 1Department of Gastroenterology and Digestive Endoscopy, Faculty of Medicine, Universidad Nacional de Colombia, Bogotá, Colombia. 2Gastroenterology Unit, Hospital Universitario Nacional de Colombia, Bogotá, Colombia. 3Gastroenterology and Digestive Endoscopy Unit, Gastroenterology Center, Bogotá, Colombia. 4Hospital Internacional de Colombia, Bucaramanga, Colombia. 5Department of Gastroenterology, Faculty of Medicine, Pontificia Universidad Católica de Chile, Santiago, Chile. 6Centro Para la Prevención y Control del Cancer (CECAN), Santiago, Chile. 7Hospital Central de la Policía, Bogotá, Colombia. 8Colombian Research Group on Helicobacter pylori, Bogotá, Colombia. 9Infectious Diseases and Cancer Research Group (GINFYCA), Centro de Investigaciones Clínicas, Fundación Hospital San Pedro, Pasto, Nariño, Colombia. | N28: 0 | Q28: Publicado | U28: Helicobacter | V28: 0 | W28: No | Z28: 0 | AB28: =AB27-Z28 -> 17862835 | AD28: 45707 | AF28: https://doi.org/10.1111/hel.70024
B29: 22 | C29: 2025 | D29: 2 | E29: 2 | G29: Q1 | H29: 3.7 | I29: 1 | J29: Randomized Trial Assessing Prospective Surveillance and Exercise for Preventing Breast Cancer-Related Lymphedema in High-Risk Patients | K29: Karol Ramırez-Parada,PT,MSc,MBA,a,b Cesar Sanchez,MD,b,c Irene Cantarero-Villanueva,PT,MSc,PhD,d,e,f_Alvaro1 Reyes,PT,MSc,PhD,gMauricio P.Pinto,PhD,hM. Loreto Bravo,PhD,hDenise Montt-Blanchard,MSc,b,i Francisco Acevedo,MD,b,c Benjamın Walbaum,MD,c,j,kMargarita Alfaro-Barra,PT,lMargarita Barra-Navarro,PT,a Scarlet Muñoz-Flores,PT,a Constanza Pinto,mSabrina Muñiz,RN,c Felipe Contreras-Briceño,PT,MSc,PhD,a,n Tomás Merino,MD,c Gina Merino,MSco | L29: 1 | M29: a Departamento de Kinesiología, Escuela Ciencias de la Salud, Facultad de Medicina, Pontificia Universidad Católica de Chile, Santiago, Chile b Centro para la prevención y el control del cáncer, CECAN, Santiago, Chile c Department of Hematology-Oncology, Faculty of Medicine, Pontificia Universidad Católica de Chile, Santiago, Chile d Department of Physical Therapy, Faculty of Health Sciences, University of Granada, Granada, Spain e Instituto de Investigación Biosanitaria (ibs.GRANADA), Granada, Spain f Sport and Health Joint University Institute (iMUDS), Granada, Spain g Exercise and Rehabilitation Sciences Laboratory, School of Physical Therapy, Faculty of Rehabilitation Sciences, Universidad Andres Bello, Santiago, Chile h Support team for Oncological Research and Medicine (STORM), Santiago, Chile i School of Design, Faculty of Architecture, Design and Urban Studies. Pontificia Universidad Católica de Chile, Santiago, Chile j Translational Genomics and Targeted Therapies in Solid Tumors Group, August Pi I Sunyer Biomedical Research Institute, Barcelona, Spain k Department of Medical Oncology, Hospital Clinic of Barcelona, Barcelona, Spain l Clínica Universidad de los Andes, Servicio de Kinesiología, Santiago, Chile m Unidad de patología mamaria, Complejo Asistencial Dr. Sótero del Río, Santiago, Chile n Laboratory of Exercise Physiology, Department of Physical Therapy, School of Health Sciences, Faculty of Medicine, Pontificia Universidad Católica de Chile, Santiago, Chile o Departamento Agencia Nacional de Prevención y Control del Cáncer, Subsecretaria de Salud Pública, Ministerio de Salud de Chile, Santiago, Chile | N29: 1 | O29: a Departamento de Kinesiología, Escuela Ciencias de la Salud, Facultad de Medicina, Pontificia Universidad Católica de Chile, Santiago, Chile b Centro para la prevención y el control del cáncer, CECAN, Santiago, Chile c Department of Hematology-Oncology, Faculty of Medicine, Pontificia Universidad Católica de Chile, Santiago, Chile d Department of Physical Therapy, Faculty of Health Sciences, University of Granada, Granada, Spain e Instituto de Investigación Biosanitaria (ibs.GRANADA), Granada, Spain f Sport and Health Joint University Institute (iMUDS), Granada, Spain g Exercise and Rehabilitation Sciences Laboratory, School of Physical Therapy, Faculty of Rehabilitation Sciences, Universidad Andres Bello, Santiago, Chile h Support team for Oncological Research and Medicine (STORM), Santiago, Chile i School of Design, Faculty of Architecture, Design and Urban Studies. Pontificia Universidad Católica de Chile, Santiago, Chile j Translational Genomics and Targeted Therapies in Solid Tumors Group, August Pi I Sunyer Biomedical Research Institute, Barcelona, Spain k Department of Medical Oncology, Hospital Clinic of Barcelona, Barcelona, Spain l Clínica Universidad de los Andes, Servicio de Kinesiología, Santiago, Chile m Unidad de patología mamaria, Complejo Asistencial Dr. Sótero del Río, Santiago, Chile n Laboratory of Exercise Physiology, Department of Physical Therapy, School of Health Sciences, Faculty of Medicine, Pontificia Universidad Católica de Chile, Santiago, Chile o Departamento Agencia Nacional de Prevención y Control del Cáncer, Subsecretaria de Salud Pública, Ministerio de Salud de Chile, Santiago, Chile | Q29: Publicado | U29: Archives of Physical Medicine and Rehabilitation | V29: 0 | W29: No | Z29: 0 | AB29: =AB28-Z29 -> 17862835 | AD29: 45727 | AF29: https://doi.org/10.1016/j.apmr.2025.03.002
B30: 23 | C30: 2025 | D30: 2 | E30: 2 | G30: Q3 | H30: 1.2 | J30: Feasibility of Solution-focused Brief Therapy for individuals with alcohol use in primary health care | K30: Karla González-Suitta,b, Rodolfo Barríac, and Vanessa Iturrietaa | L30: 0 | N30: 1 | O30: cDepartamento de Matemática y Ciencia de la Computación, Universidad de Santiago de Chile, Santiago, Chile | Q30: Publicado | U30: Journal of Ethnic & Cultural Diversity in Social Work | V30: 0 | Z30: 0 | AB30: =AB29-Z30 -> 17862835 | AD30: 45807 | AF30: https://doi.org/10.1080/15313204.2025.2510210
B31: 24 | C31: 2025 | D31: 3 | E31: 3 | G31: Q3 | H31: 3 | J31: Towards Personalized Precision Oncology: A Feasibility Study of NGS-Based Variant Analysis of FFPE CRC Samples in a Chilean Public Health System Laboratory | K31: Eduardo Durán Jara 1 Iván Ponce 1 , Marcelo Rojas Herrera 1 , Jessica Toro 2, 3 , Paulo Covarrubias 1 , Evelin González 2 , Natalia T. Santis Alay 4 5 , Mario E. Soto Marchant 4 6 , Katherine Marcelain 2, 3 , Bárbara Parra 1 and Jorge Fernández 1 | L31: 0 | N31: 1 | O31: Subdepartamento de Genómica y Genética Molecular, Laboratorio Nacional Biomédico y de Referencia, Instituto de Salud Pública de Chile, y Departamento Agencia Nacional de Dispositivos Médicos, Instituto de Salud Pública de Chile. Escuela de Tecnología Médica, Facultad de Salud y Odontología, Universidad Diego Portales Santiago , Chile | Q31: Publicado | U31: Curr. Issues Mol. Biol | V31: 0 | W31: No | Z31: 0 | AB31: =AB30-Z31 -> 17862835 | AD31: 45868 | AF31: https://doi.org/10.3390/cimb47080599
B32: 25 | C32: 2025 | D32: 3 | E32: 3 | G32: Q1 | H32: 6.6 | I32: 0 | J32: Oxidative stress, parity history and remnant follicles in the aged ovary. Insights on ovarian cancer risk and protection. | K32: Ulises Urzúa , Arnaldo Andrés Marín, Enrique Castellón $ 3.224.953 (50%) | L32: 0 | N32: 0 | Q32: Publicado | S32: 3648338 | T32: 45826 | U32: Antoxidants | V32: 0.5 | W32: Enrique Castellón | X32: 9-2025 | Y32: USD 3446,42 | Z32: 3244953 | AB32: =AB31-Z32 -> 14617882 | AD32: 45833 | AF32: https://doi.org/10.3390/antiox14070759
B33: 26 | C33: 2025 | D33: 2 | E33: 2 | G33: Q1 | H33: 7.6 | I33: 1 | J33: Assessing the Impact of a Single Qualitative Fecal Immunochemical Test on Colonoscopy Prioritization and Mortality in Risk-Stratified Patients with Suspected Colorectal Cancer: A Retrospective Cohort Study | K33: Felipe F. Quezada-Diaz MD 1-3, Johanna Acevedo, MSc2-3, Maite González, MSc 2, Andrea Tello 1, Richard CastilloMD 1, Carlos Morales Mora MD1, Erik Manríquez Alegría MD 1, Valentina Duran Espinoza MD, MSc4, Felipe Mena MD1, Catherine Le- Bert 1, Manuel Cabreras MD 1, Ángelo Fulle MD1, Gonzalo Carvajal MD1, Pamela Briones MD1, Bruno Nervi MD3.4, Rodrigo Kusanovich MD 1. | L33: 0 | N33: 1 | O33: 1Servicio de Cirugía, Unidad de Coloproctología, Complejo Asistencial Doctor Sótero Del Río, Santiago, Chile. 2Centro para la Prevención y el Control del Cáncer (CECAN), Santiago, Chile. 3Instituto de Ciencias e Innovación en Medicina, Facultad de Medicina Clínica Alemana Universidad del Desarrollo, Santiago, Chile. 4Escuela de Medicina. Pontificia Universidad Católica de Chile, Santiago, Chile. 5Departamento de Hematología y Oncología, Facultad de Medicina, Pontificia Universidad Católica de Chile, Santiago, Chile. | Q33: Publicado | S33: OAD0000611643 | T33: 45860 | U33: Lancet Regional Health Americas | V33: 1 | W33: Bruno Nervi | X33: 10-2025 | Y33: USD 2465 | Z33: 2350131 | AB33: =AB32-Z33 -> 12267751 | AD33: 45880 | AF33: https://doi.org/10.1016/j.lana.2025.101201
B34: 27 | C34: 2025 | D34: 2 | E34: 2 | G34: Q2 | H34: 2.3 | J34: The challenges of cancer survivorship care in Chile: A longitudinal study comparing the quality of care and quality of life for cancer survivors in a primary care network and a Cancer Center in Chile. | K34: Puschel Klaus1,2, Arancibia Victor2, Rioseco Andrea1,2, Paz Sarah2, Soto María Gabriela1.2, Martinez Javiera2,3, Faundez Marcela1, Acevedo Francisco2, Di Biase Felipe2,3, Emery Jon2,4, León Augusto5, Are Chandrekanth6, Thompson Beti7 | L34: 1 | M34: 1Department of Family and Community Medicine, Pontificia Universidad Catolica De Chile School of Medicine, Santiago, Chile kpuschel@uc.cl. 2Center for Cancer Prevention and Control (CECAN), Santiago, Chile. 3Department of Family and Community Medicine, Pontificia Universidad Catolica De Chile School of Medicine, Santiago, Chile. 4The University of Melbourne, Medical School, Melbourne, Victoria, Australia. 5Department of Oncology, Pontificia Universidad Catolica De Chile School of Medicine, Santiago, Chile. 6Universidad de los Andes, Santiago, Chile. 7Department of Surgical Oncology, Pontificia Universidad Catolica de Chile, School of Medicine, Santiago, Chile. 8Division of Surgical Oncology, University of Nebraska Medical Center, Omaha, Nebraska, USA. 9Fred Hutchinson Cancer Research Center, Seattle, Washington, USA. | N34: 1 | O34: 1Department of Family and Community Medicine, Pontificia Universidad Catolica De Chile School of Medicine, Santiago, Chile kpuschel@uc.cl. 2Center for Cancer Prevention and Control (CECAN), Santiago, Chile. 3Department of Family and Community Medicine, Pontificia Universidad Catolica De Chile School of Medicine, Santiago, Chile. 4The University of Melbourne, Medical School, Melbourne, Victoria, Australia. 5Department of Oncology, Pontificia Universidad Catolica De Chile School of Medicine, Santiago, Chile. 6Universidad de los Andes, Santiago, Chile. 7Department of Surgical Oncology, Pontificia Universidad Catolica de Chile, School of Medicine, Santiago, Chile. 8Division of Surgical Oncology, University of Nebraska Medical Center, Omaha, Nebraska, USA. 9Fred Hutchinson Cancer Research Center, Seattle, Washington, USA. | Q34: Publicado | S34: APC600692271 | T34: 45860 | U34: BMJ Open | V34: 1 | W34: Klaus Puschel | X34: 11-2025 | Y34: USD 3125 | Z34: 2979375 | AB34: =AB33-Z34 -> 9288376 | AD34: 45879 | AF34: https://doi.org/10.1136/bmjopen-2024-097015
B35: 28 | C35: 2025 | D35: 3 | E35: 3 | G35: Q2 | H35: 3.3 | J35: Genetic variants and clinical determinants affecting the response to 5-Fluorouracilbased treatment in Chilean patients with advanced colorectal cancer | K35: Leslie C. Cerpa1,2,3, Christopher Sandoval4, Paula Escalante1, Juan P. Cayún1,2, María A. Lavanderos1,2,5, Claudio Alarcón-Concha1,6, Guillermo Kaempfe1, Diego Moreno-Tapia1, Camilo S. Quiroz1, Carolina Gutierrez-Cáceres1,7, Olga Barajas3,8, Bettina Müller3,9, Alicia Colombo3,10, Gerardo Donoso3,10, Angie Nuñez11, Nelson M. Varela1,2 and Luis A. Quiñones1,2,7* | L35: 1 | M35: 1Laboratory of Chemical Carcinogenesis and Pharmacogenetics, Department of Basic-Clinical Oncology (DOBC), Faculty of Medicine, University of Chile, Santiago, Chile, 2Latin American Network for Implementation and Validation of Clinical Pharmacogenomics Guidelines (RELIVAF), Santiago, Chile, 3Center for Cancer Prevention and Control (CECAN), Santiago, Chile, 4Clinical Laboratory, Felix Bulnes Clinical Hospital, Santiago, Chile, 5Department of Basic Sciences, Faculty of Sciences, University of Bío, Bío, Chile, 6Escuela de Medicina, Fundación Instituto Profesional Duoc UC, Santiago, Chile, 7Department of Pharmaceutical Sciences and Technology, Faculty of Chemical and Pharmaceutical Sciences, University of Chile, Santiago, Chile, 8Clinical Hospital of University of Chile, Santiago, Chile, 9National Cancer Institute, Santiago, Chile, 10Biobank of Fluids and Tissues of the University of Chile, Santiago, Chile, 11Faculty of Pharmacy, University of Costa Rica, San Jose, Costa Rica | N35: 1 | O35: 1Laboratory of Chemical Carcinogenesis and Pharmacogenetics, Department of Basic-Clinical Oncology (DOBC), Faculty of Medicine, University of Chile, Santiago, Chile, 2Latin American Network for Implementation and Validation of Clinical Pharmacogenomics Guidelines (RELIVAF), Santiago, Chile, 3Center for Cancer Prevention and Control (CECAN), Santiago, Chile, 4Clinical Laboratory, Felix Bulnes Clinical Hospital, Santiago, Chile, 5Department of Basic Sciences, Faculty of Sciences, University of Bío, Bío, Chile, 6Escuela de Medicina, Fundación Instituto Profesional Duoc UC, Santiago, Chile, 7Department of Pharmaceutical Sciences and Technology, Faculty of Chemical and Pharmaceutical Sciences, University of Chile, Santiago, Chile, 8Clinical Hospital of University of Chile, Santiago, Chile, 9National Cancer Institute, Santiago, Chile, 10Biobank of Fluids and Tissues of the University of Chile, Santiago, Chile, 11Faculty of Pharmacy, University of Costa Rica, San Jose, Costa Rica | P35: 0.5 | Q35: Publicado | U35: Frontiers in Oncology | V35: 1 | W35: Lluis Quiñones | X35: 13-2025 | Y35: USD 2172,97 | Z35: 2080966 | AB35: =AB34-Z35 -> 7207410 | AD35: 45863 | AF35: https://doi.org/10.3389/fonc.2025.1589724
